<?xml version="1.0" encoding="utf-8"?>
<!-- This URDF was automatically created by SolidWorks to URDF Exporter! Originally created by Stephen Brawner (brawner@gmail.com) 
     Commit Version: 1.6.0-1-g15f4949  Build Version: 1.6.7594.29634
     For more information, please see http://wiki.ros.org/sw_urdf_exporter -->
<robot
  name="car_assem">
  <link name="dummy_link">
  </link>
  <joint name="dummy_joint" type="fixed">
        <origin
        xyz="0 0 0"
        rpy="1.5 0 0" />
	  <parent link="dummy_link" />
	  <child link="base_link" />
  </joint>
  <link
    name="base_link">
    <inertial>
      <origin
        xyz="0.434959557233976 0.480154416166651 0.780915642325222"
        rpy="0 0 0" />
      <mass
        value="18.9957633941014" />
      <inertia
        ixx="0.321480497658355"
        ixy="0.00882534016113909"
        ixz="4.49226682056294E-08"
        iyy="1.73624351581292"
        iyz="-7.09701033323967E-08"
        izz="1.42813532065719" />
    </inertial>
    <visual>
      <origin
        xyz="0 0 0"
        rpy="0 0 0" />
      <geometry>
        <mesh
          filename="package://car_assem/meshes/base_link.STL" />
      </geometry>
      <material
        name="">
        <color
          rgba="0.792156862745098 0.819607843137255 0.933333333333333 1" />
      </material>
    </visual>
    <collision>
      <origin
        xyz="0 0 0"
        rpy="0 0 0" />
      <geometry>
        <mesh
          filename="package://car_assem/meshes/base_link.STL" />
      </geometry>
    </collision>
  </link>
  <link
    name="front_left_steering_link">
    <inertial>
      <origin
        xyz="0.0789613521158623 0.0201784329051714 -7.01327474983415E-08"
        rpy="0 0 0" />
      <mass
        value="0.130435980995533" />
      <inertia
        ixx="3.04982371151654E-05"
        ixy="4.9215344508306E-05"
        ixz="-8.19738919368111E-10"
        iyy="0.000537452105458136"
        iyz="3.34922488643002E-10"
        izz="0.000556335665656311" />
    </inertial>
    <visual>
      <origin
        xyz="0 0 0"
        rpy="0 0 0" />
      <geometry>
        <mesh
          filename="package://car_assem/meshes/front_left_steering_link.STL" />
      </geometry>
      <material
        name="">
        <color
          rgba="0.792156862745098 0.819607843137255 0.933333333333333 1" />
      </material>
    </visual>
    <collision>
      <origin
        xyz="0 0 0"
        rpy="0 0 0" />
      <geometry>
        <mesh
          filename="package://car_assem/meshes/front_left_steering_link.STL" />
      </geometry>
    </collision>
  </link>
  <joint
    name="front_left_steering"
    type="revolute">
    <origin
      xyz="0.091551 0.41654 0.92953"
      rpy="0 -1.5464 0" />
    <parent
      link="base_link" />
    <child
      link="front_left_steering_link" />
    <axis
      xyz="0 1 0" />
    <limit
      lower="-0.35"
      upper="0.35"
      effort="0"
      velocity="0" />
  </joint>
  <link
    name="front_left_wheel_link">
    <inertial>
      <origin
        xyz="0.0429772351798592 -0.00991361852421707 7.7715611723761E-16"
        rpy="0 0 0" />
      <mass
        value="2.31289269458194" />
      <inertia
        ixx="0.0122648275270047"
        ixy="-7.47197150787787E-06"
        ixz="-1.78893358460108E-18"
        iyy="0.00714411189689047"
        iyz="-3.68565211174027E-19"
        izz="0.00715609598929908" />
    </inertial>
    <visual>
      <origin
        xyz="0 0 0"
        rpy="0 0 0" />
      <geometry>
        <mesh
          filename="package://car_assem/meshes/front_left_wheel_link.STL" />
      </geometry>
      <material
        name="">
        <color
          rgba="0.792156862745098 0.819607843137255 0.933333333333333 1" />
      </material>
    </visual>
    <collision>
      <origin
        xyz="0 0 0"
        rpy="0 0 0" />
      <geometry>
        <mesh
          filename="package://car_assem/meshes/front_left_wheel_link.STL" />
      </geometry>
    </collision>
  </link>
  <joint
    name="front_left_wheel"
    type="continuous">
    <origin
      xyz="0.084724 0.020158 -0.0087955"
      rpy="-1.0749 0 0" />
    <parent
      link="front_left_steering_link" />
    <child
      link="front_left_wheel_link" />
    <axis
      xyz="1 0 0" />
  </joint>
  <link
    name="front_right_steering_link">
    <inertial>
      <origin
        xyz="0.0789613530952155 0.0201784328893301 -7.01499886096579E-08"
        rpy="0 0 0" />
      <mass
        value="0.13043597902095" />
      <inertia
        ixx="3.04982371036657E-05"
        ixy="4.9215344446361E-05"
        ixz="-8.19722506991863E-10"
        iyy="0.000537452104619414"
        iyz="3.34926809928542E-10"
        izz="0.00055633566482944" />
    </inertial>
    <visual>
      <origin
        xyz="0 0 0"
        rpy="0 0 0" />
      <geometry>
        <mesh
          filename="package://car_assem/meshes/front_right_steering_link.STL" />
      </geometry>
      <material
        name="">
        <color
          rgba="0.792156862745098 0.819607843137255 0.933333333333333 1" />
      </material>
    </visual>
    <collision>
      <origin
        xyz="0 0 0"
        rpy="0 0 0" />
      <geometry>
        <mesh
          filename="package://car_assem/meshes/front_right_steering_link.STL" />
      </geometry>
    </collision>
  </link>
  <joint
    name="front_right_steering"
    type="revolute">
    <origin
      xyz="0.091551 0.41654 0.6323"
      rpy="3.1416 1.548 3.1416" />
    <parent
      link="base_link" />
    <child
      link="front_right_steering_link" />
    <axis
      xyz="0 1 0" />
    <limit
      lower="-0.35"
      upper="0.35"
      effort="0"
      velocity="0" />
  </joint>
  <link
    name="front_right_wheel_link">
    <inertial>
      <origin
        xyz="0.042763266193903 -0.00991361852421607 -1.11022302462516E-16"
        rpy="0 0 0" />
      <mass
        value="2.31289269458194" />
      <inertia
        ixx="0.0122648275270047"
        ixy="-7.4719715079482E-06"
        ixz="2.76810367162705E-17"
        iyy="0.00714411189689047"
        iyz="9.77052504657835E-19"
        izz="0.00715609598929908" />
    </inertial>
    <visual>
      <origin
        xyz="0 0 0"
        rpy="0 0 0" />
      <geometry>
        <mesh
          filename="package://car_assem/meshes/front_right_wheel_link.STL" />
      </geometry>
      <material
        name="">
        <color
          rgba="0.792156862745098 0.819607843137255 0.933333333333333 1" />
      </material>
    </visual>
    <collision>
      <origin
        xyz="0 0 0"
        rpy="0 0 0" />
      <geometry>
        <mesh
          filename="package://car_assem/meshes/front_right_wheel_link.STL" />
      </geometry>
    </collision>
  </link>
  <joint
    name="front_right_wheel"
    type="continuous">
    <origin
      xyz="0.084938 0.021602 -0.0078446"
      rpy="-0.90183 0 0" />
    <parent
      link="front_right_steering_link" />
    <child
      link="front_right_wheel_link" />
    <axis
      xyz="1 0 0" />
  </joint>
  <link
    name="back_left_wheel_link">
    <inertial>
      <origin
        xyz="0.0362610763466902 -0.0100576053882299 6.43690811298336E-05"
        rpy="0 0 0" />
      <mass
        value="2.31289269458194" />
      <inertia
        ixx="0.0122648275270047"
        ixy="4.98284864490567E-06"
        ixz="-5.56790603340364E-06"
        iyy="0.00715076644439137"
        iyz="5.95530937454549E-06"
        izz="0.00714944144179819" />
    </inertial>
    <visual>
      <origin
        xyz="0 0 0"
        rpy="0 0 0" />
      <geometry>
        <mesh
          filename="package://car_assem/meshes/back_left_wheel_link.STL" />
      </geometry>
      <material
        name="">
        <color
          rgba="0.792156862745098 0.819607843137255 0.933333333333333 1" />
      </material>
    </visual>
    <collision>
      <origin
        xyz="0 0 0"
        rpy="0 0 0" />
      <geometry>
        <mesh
          filename="package://car_assem/meshes/back_left_wheel_link.STL" />
      </geometry>
    </collision>
  </link>
  <joint
    name="back_left_wheel"
    type="continuous">
    <origin
      xyz="0.60728 0.42837 1.0349"
      rpy="2.7212 -1.5708 0" />
    <parent
      link="base_link" />
    <child
      link="back_left_wheel_link" />
    <axis
      xyz="1 0 0" />
  </joint>
  <link
    name="back_right_wheel_link">
    <inertial>
      <origin
        xyz="-0.0399389236533098 -0.00991361852421546 2.77555756156289E-17"
        rpy="0 0 0" />
      <mass
        value="2.31289269458194" />
      <inertia
        ixx="0.0122648275270047"
        ixy="-7.47197150789892E-06"
        ixz="2.4818065354551E-19"
        iyy="0.00714411189689046"
        iyz="0"
        izz="0.00715609598929908" />
    </inertial>
    <visual>
      <origin
        xyz="0 0 0"
        rpy="0 0 0" />
      <geometry>
        <mesh
          filename="package://car_assem/meshes/back_right_wheel_link.STL" />
      </geometry>
      <material
        name="">
        <color
          rgba="0.792156862745098 0.819607843137255 0.933333333333333 1" />
      </material>
    </visual>
    <collision>
      <origin
        xyz="0 0 0"
        rpy="0 0 0" />
      <geometry>
        <mesh
          filename="package://car_assem/meshes/back_right_wheel_link.STL" />
      </geometry>
    </collision>
  </link>
  <joint
    name="back_right_wheel"
    type="continuous">
    <origin
      xyz="0.62095 0.42207 0.45072"
      rpy="1.2833 1.5708 0" />
    <parent
      link="base_link" />
    <child
      link="back_right_wheel_link" />
    <axis
      xyz="1 0 0" />
  </joint>
</robot>
