<?xml version="1.0" encoding="utf-8"?>
<!-- This URDF was automatically created by SolidWorks to URDF Exporter! Originally created by Stephen Brawner (brawner@gmail.com) 
     Commit Version: 1.6.0-1-g15f4949  Build Version: 1.6.7594.29634
     For more information, please see http://wiki.ros.org/sw_urdf_exporter -->
<robot
  name="car_assem">
    <link name="dummy_link">
  </link>
  <joint name="dummy_joint" type="fixed">
    <origin rpy="0 0 0" xyz="0 0 0"/>
    <parent link="dummy_link"/>
    <child link="base_link"/>
  </joint>
  <link
    name="base_link">
    <inertial>
      <origin
        xyz="-0.00928225892424905 -3.84853373613936E-08 -0.0279829948416439"
        rpy="0 0 0" />
      <mass
        value="18.9957633941014" />
      <inertia
        ixx="0.321480497658355"
        ixy="-4.49226682044018E-08"
        ixz="-0.00882534016113908"
        iyy="1.42813532065719"
        iyz="-7.09701033377331E-08"
        izz="1.73624351581292" />
    </inertial>
    <visual>
      <origin
        xyz="0 0 0"
        rpy="0 0 0" />
      <geometry>
        <mesh
          filename="package://car_assem/meshes/base_link.STL" />
      </geometry>
      <material
        name="">
        <color
          rgba="0.792156862745098 0.819607843137255 0.933333333333333 1" />
      </material>
    </visual>
    <collision>
      <origin
        xyz="0 0 0"
        rpy="0 0 0" />
      <geometry>
        <mesh
          filename="package://car_assem/meshes/base_link.STL" />
      </geometry>
    </collision>
  </link>
  <link
    name="front_left_steering_link">
    <inertial>
      <origin
        xyz="0.0789613521158623 -0.0460215670948286 -7.01327474983415E-08"
        rpy="0 0 0" />
      <mass
        value="0.130435980995533" />
      <inertia
        ixx="3.04982371151654E-05"
        ixy="4.9215344508306E-05"
        ixz="-8.19738919364723E-10"
        iyy="0.000537452105458135"
        iyz="3.34922488643002E-10"
        izz="0.000556335665656311" />
    </inertial>
    <visual>
      <origin
        xyz="0 0 0"
        rpy="0 0 0" />
      <geometry>
        <mesh
          filename="package://car_assem/meshes/front_left_steering_link.STL" />
      </geometry>
      <material
        name="">
        <color
          rgba="0.792156862745098 0.819607843137255 0.933333333333333 1" />
      </material>
    </visual>
    <collision>
      <origin
        xyz="0 0 0"
        rpy="0 0 0" />
      <geometry>
        <mesh
          filename="package://car_assem/meshes/front_left_steering_link.STL" />
      </geometry>
    </collision>
  </link>
  <joint
    name="front_left_steering"
    type="revolute">
    <origin
      xyz="0.33413 0.14861 -0.0254"
      rpy="1.5708 0 1.5952" />
    <parent
      link="base_link" />
    <child
      link="front_left_steering_link" />
    <axis
      xyz="0 1 0" />
    <limit
      lower="-0.35"
      upper="0.35"
      effort="0"
      velocity="0" />
  </joint>
  <link
    name="front_left_wheel_link">
    <inertial>
      <origin
        xyz="0.0429772351798594 8.63814757829373E-05 7.7715611723761E-16"
        rpy="0 0 0" />
      <mass
        value="2.31289269458194" />
      <inertia
        ixx="0.0122648275270047"
        ixy="-7.4719715078779E-06"
        ixz="-1.76860479386698E-18"
        iyy="0.00714411189689047"
        iyz="-3.68776969410841E-19"
        izz="0.00715609598929908" />
    </inertial>
    <visual>
      <origin
        xyz="0 0 0"
        rpy="0 0 0" />
      <geometry>
        <mesh
          filename="package://car_assem/meshes/front_left_wheel_link.STL" />
      </geometry>
      <material
        name="">
        <color
          rgba="0.792156862745098 0.819607843137255 0.933333333333333 1" />
      </material>
    </visual>
    <collision>
      <origin
        xyz="0 0 0"
        rpy="0 0 0" />
      <geometry>
        <mesh
          filename="package://car_assem/meshes/front_left_wheel_link.STL" />
      </geometry>
    </collision>
  </link>
  <joint
    name="front_left_wheel"
    type="continuous">
    <origin
      xyz="0.084724 -0.0508 0"
      rpy="-1.0749 0 0" />
    <parent
      link="front_left_steering_link" />
    <child
      link="front_left_wheel_link" />
    <axis
      xyz="1 0 0" />
  </joint>
  <link
    name="front_right_steering_link">
    <inertial>
      <origin
        xyz="0.0789613530952155 -0.04602156711067 -7.01499886096579E-08"
        rpy="0 0 0" />
      <mass
        value="0.13043597902095" />
      <inertia
        ixx="3.04982371036657E-05"
        ixy="4.9215344446361E-05"
        ixz="-8.19722506991863E-10"
        iyy="0.000537452104619414"
        iyz="3.34926809928542E-10"
        izz="0.00055633566482944" />
    </inertial>
    <visual>
      <origin
        xyz="0 0 0"
        rpy="0 0 0" />
      <geometry>
        <mesh
          filename="package://car_assem/meshes/front_right_steering_link.STL" />
      </geometry>
      <material
        name="">
        <color
          rgba="0.792156862745098 0.819607843137255 0.933333333333333 1" />
      </material>
    </visual>
    <collision>
      <origin
        xyz="0 0 0"
        rpy="0 0 0" />
      <geometry>
        <mesh
          filename="package://car_assem/meshes/front_right_steering_link.STL" />
      </geometry>
    </collision>
  </link>
  <joint
    name="front_right_steering"
    type="revolute">
    <origin
      xyz="0.33413 -0.14861 -0.0254"
      rpy="1.5708 0 -1.548" />
    <parent
      link="base_link" />
    <child
      link="front_right_steering_link" />
    <axis
      xyz="0 1 0" />
    <limit
      lower="-0.35"
      upper="0.35"
      effort="0"
      velocity="0" />
  </joint>
  <link
    name="front_right_wheel_link">
    <inertial>
      <origin
        xyz="0.042763266193903 8.63814757839365E-05 -1.11022302462516E-16"
        rpy="0 0 0" />
      <mass
        value="2.31289269458194" />
      <inertia
        ixx="0.0122648275270047"
        ixy="-7.4719715079482E-06"
        ixz="2.76810367162705E-17"
        iyy="0.00714411189689047"
        iyz="9.77052504657835E-19"
        izz="0.00715609598929908" />
    </inertial>
    <visual>
      <origin
        xyz="0 0 0"
        rpy="0 0 0" />
      <geometry>
        <mesh
          filename="package://car_assem/meshes/front_right_wheel_link.STL" />
      </geometry>
      <material
        name="">
        <color
          rgba="0.792156862745098 0.819607843137255 0.933333333333333 1" />
      </material>
    </visual>
    <collision>
      <origin
        xyz="0 0 0"
        rpy="0 0 0" />
      <geometry>
        <mesh
          filename="package://car_assem/meshes/front_right_wheel_link.STL" />
      </geometry>
    </collision>
  </link>
  <joint
    name="front_right_wheel"
    type="continuous">
    <origin
      xyz="0.084938 -0.0508 0"
      rpy="-0.90183 0 0" />
    <parent
      link="front_right_steering_link" />
    <child
      link="front_right_wheel_link" />
    <axis
      xyz="1 0 0" />
  </joint>
  <link
    name="back_left_wheel_link">
    <inertial>
      <origin
        xyz="0.0362610763466902 -5.7605388229881E-05 6.43690811298336E-05"
        rpy="0 0 0" />
      <mass
        value="2.31289269458194" />
      <inertia
        ixx="0.0122648275270047"
        ixy="4.98284864490567E-06"
        ixz="-5.56790603340364E-06"
        iyy="0.00715076644439137"
        iyz="5.95530937454549E-06"
        izz="0.00714944144179819" />
    </inertial>
    <visual>
      <origin
        xyz="0 0 0"
        rpy="0 0 0" />
      <geometry>
        <mesh
          filename="package://car_assem/meshes/back_left_wheel_link.STL" />
      </geometry>
      <material
        name="">
        <color
          rgba="0.792156862745098 0.819607843137255 0.933333333333333 1" />
      </material>
    </visual>
    <collision>
      <origin
        xyz="0 0 0"
        rpy="0 0 0" />
      <geometry>
        <mesh
          filename="package://car_assem/meshes/back_left_wheel_link.STL" />
      </geometry>
    </collision>
  </link>
  <joint
    name="back_left_wheel"
    type="continuous">
    <origin
      xyz="-0.18569 0.254 -0.0889"
      rpy="1.9912 0 1.5708" />
    <parent
      link="base_link" />
    <child
      link="back_left_wheel_link" />
    <axis
      xyz="1 0 0" />
  </joint>
  <link
    name="back_right_wheel_link">
    <inertial>
      <origin
        xyz="0.0362610763466903 8.63814757844361E-05 2.77555756156289E-17"
        rpy="0 0 0" />
      <mass
        value="2.31289269458194" />
      <inertia
        ixx="0.0122648275270047"
        ixy="-7.47197150789892E-06"
        ixz="2.48604170019137E-19"
        iyy="0.00714411189689046"
        iyz="0"
        izz="0.00715609598929908" />
    </inertial>
    <visual>
      <origin
        xyz="0 0 0"
        rpy="0 0 0" />
      <geometry>
        <mesh
          filename="package://car_assem/meshes/back_right_wheel_link.STL" />
      </geometry>
      <material
        name="">
        <color
          rgba="0.792156862745098 0.819607843137255 0.933333333333333 1" />
      </material>
    </visual>
    <collision>
      <origin
        xyz="0 0 0"
        rpy="0 0 0" />
      <geometry>
        <mesh
          filename="package://car_assem/meshes/back_right_wheel_link.STL" />
      </geometry>
    </collision>
  </link>
  <joint
    name="back_right_wheel"
    type="continuous">
    <origin
      xyz="-0.18569 -0.254 -0.0889"
      rpy="2.8541 0 -1.5708" />
    <parent
      link="base_link" />
    <child
      link="back_right_wheel_link" />
    <axis
      xyz="1 0 0" />
  </joint>
    <link name="base_laser">
    <inertial>
      <origin rpy="0 0 0" xyz="-0.00029774 0.0066667 0.00013047"/>
      <mass value="0.15717"/>
      <inertia ixx="6.7885E-05" ixy="-1.3987E-07" ixz="-8.1554E-07" iyy="0.00013173" iyz="-9.0932E-08" izz="7.1972E-05"/>
    </inertial>
    <visual>
      <origin rpy="0 0 0" xyz="0 0 0"/>
      <geometry>
        <mesh filename="package://car_assem/meshes/ydlidar.dae"/>
      </geometry>
      <material name="">
        <color rgba="0.64706 0.61961 0.58824 1"/>
      </material>
    </visual>
    <collision>
      <origin rpy="0 0 0" xyz="0 0 0"/>
      <geometry>
        <mesh filename="package://car_assem/meshes/ydlidar.dae"/>
      </geometry>
    </collision>
  </link>
  <link name="laser_frame">
    <inertial>
      <origin rpy="0 0 0" xyz="-0.00036659 0.00064155 -0.00027052"/>
      <mass value="0.25482"/>
      <inertia ixx="8.9194E-05" ixy="1.8116E-07" ixz="3.6435E-08" iyy="0.00018279" iyz="2.423E-07" izz="0.00011103"/>
    </inertial>
    <!--visual>
      <origin
        xyz="0 0 0"
        rpy="0 0 0" />
      <geometry>
        <mesh
          filename="package://ydlidar_ros/meshes/ydlidar.dae" />
      </geometry>
      <material
        name="">
        <color
          rgba="0.64706 0.61961 0.58824 1" />
      </material>
    </visual-->
    <!--collision>
      <origin
        xyz="0 0 0"
        rpy="0 0 0" />
      <geometry>
        <mesh
          filename="package://ydlidar_ros/meshes/ydlidar.dae" />
      </geometry>
    </collision-->
  </link>
  <joint name="laser_joint" type="fixed">
    <origin rpy="0 0 0" xyz="0 0 0.03172"/>
    <parent link="base_laser"/>
    <child link="laser_frame"/>
    <axis xyz="0 0 0"/>
  </joint>
  <!-- Add your gazebo sensors here -->

  <!-- Create a joint between your robot and sensor -->
  <joint name="lidarGlue" type="fixed">
    <parent link="base_link"/>
    <child link="base_laser"/>
    <origin rpy="0 0 0" xyz="0 0 0"/>
  </joint>


</robot>